<mujoco model="sonar_radar">

  <compiler angle="degree" meshdir="meshes/"/>

  <option timestep="0.001" gravity="0 0 -9.81"/>

  <visual>
    <headlight diffuse="0.7 0.7 0.7" ambient="0.3 0.3 0.3" specular="0.1 0.1 0.1"/>
  </visual>

  <asset>
    <mesh name="radar_base_gray_mesh" file="radar_base_gray.stl" scale="1 1 1"/>
    <mesh name="radar_base_red_mesh"  file="radar_base_red.stl"  scale="1 1 1"/>
    <mesh name="radar_base_blue_mesh" file="radar_base_blue.stl" scale="1 1 1"/>
    <mesh name="radar_dome_mesh"  file="radar_dome.stl"  scale="1 1 1"/>
    <mesh name="bevel_gear_12_mesh" file="bevel_gear_12.stl" scale="1 1 1"/>
  </asset>

  <worldbody>

    <light name="light_top"  pos="0 0 1.5" dir="0 0 -1"
           diffuse="0.8 0.8 0.8" specular="0.2 0.2 0.2" directional="true"/>
    <light name="light_fill" pos="1 -1 0.8" dir="-1 1 -0.8"
           diffuse="0.4 0.4 0.4" specular="0.0 0.0 0.0" directional="true"/>

    <geom name="floor" type="plane" size="1 1 0.01"
          rgba="0.6 0.6 0.6 1" contype="1" conaffinity="1"/>

    <!-- 障害物: ソナーの計測範囲内（正面付近、約120mm）に配置。
         wall_x / wall_y で水平面内を移動可能（向きは固定）。 -->
    <body name="wall_body" pos="0.0037 -0.1203 0.04">
      <joint name="wall_x" type="slide" axis="1 0 0" range="-0.06 0.06" damping="5.0"/>
      <joint name="wall_y" type="slide" axis="0 1 0" range="-0.05 0.10" damping="5.0"/>
      <inertial pos="0 0 0" mass="0.05" diaginertia="0.0001 0.0001 0.0001"/>
      <!-- 実機の壁: 幅48mm(6ポッチ)×高さ80mm(10ポッチ)、厚さは無視 -->
      <geom name="wall" type="box"
            size="0.024 0.005 0.04"
            rgba="0.8 0.8 0.2 0.3"
            contype="1" conaffinity="1"/>
    </body>

    <!-- 台座: ワールドに固定 -->
    <body name="radar_base" pos="0 0 0" euler="0 0 0">
      <inertial pos="0 0 0" mass="1.0" diaginertia="0.01 0.01 0.01"/>
      <geom name="base_gray_geom" type="mesh" mesh="radar_base_gray_mesh"
            contype="0" conaffinity="0" rgba="0.366 0.361 0.371 1"/>
      <geom name="base_red_geom"  type="mesh" mesh="radar_base_red_mesh"
            contype="0" conaffinity="0" rgba="0.578 0.010 0.002 1"/>
      <geom name="base_blue_geom" type="mesh" mesh="radar_base_blue_mesh"
            contype="0" conaffinity="0" rgba="0.000 0.089 0.515 1"/>

      <!-- モーターローター（旋回、12Tベベルギアを保持）。
           メッシュは libspikehat_sim/examples/test_motor.xml 側へ移動済み。
           sonar_radar07側のモーター本体表現は別途検討する。 -->
      <body name="motor_rotor" pos="-0.0080 -0.0238 0.0237" euler="0 0 0">
        <inertial pos="0 0 0" mass="0.05" diaginertia="0.0005 0.0005 0.0005"/>
        <joint name="motor_joint" type="hinge" axis="0 0 1"
               damping="0.85" armature="0.001"/>
        <geom name="bevel_gear_12_geom" type="mesh" mesh="bevel_gear_12_mesh"
              contype="0" conaffinity="0" rgba="0.9 0.7 0.1 1"/>
      </body>

      <!-- ドーム（36Tベベルギアを保持、motor_rotorとはギア比1:3・回転方向反転で連動） -->
      <body name="radar_dome" pos="-0.0083 0.0007 0.0358" euler="0 0 180">
        <inertial pos="0 0 0" mass="0.1" diaginertia="0.001 0.001 0.001"/>
        <joint name="dome_joint" type="hinge" axis="0 0 -1"
               damping="0.1" armature="0.0005"/>
        <geom name="dome_geom" type="mesh" mesh="radar_dome_mesh"
              contype="0" conaffinity="0" rgba="0.2 0.5 0.2 1"/>
        <site name="sonar_site" pos="-0.0022 0.0247 0.0162" size="0.01" rgba="1 0 0 1"/>
        <site name="color_site" pos="0.0035 -0.0398 0.0242" size="0.01" rgba="1 1 0 1"/>
      </body>

    </body>

    <!-- 終了スイッチ（フォースセンサー）: sonar_radar.py のスキャン終了トリガー。
         Controlタブの press_ctrl を動かして押すとスキャンが終了する。 -->
    <body name="force_sensor_body" pos="0.10 0 0.010">
      <inertial pos="0 0 0" mass="0.05" diaginertia="0.0005 0.0005 0.0005"/>
      <geom name="force_sensor_geom" type="box" pos="0 0 0" size="0.015 0.015 0.005"
            rgba="0.3 0.3 0.8 1" contype="1" conaffinity="1"/>
      <site name="force_site" pos="0 0 0.005" size="0.013 0.013 0.001" type="box" rgba="1 0.5 0 0.5"/>
    </body>

    <body name="press_body" pos="0.10 0 0.040">
      <joint name="press_slide" type="slide" axis="0 0 -1" range="0.0 0.030" damping="5.0"/>
      <inertial pos="0 0 0" mass="0.02" diaginertia="0.0001 0.0001 0.0001"/>
      <geom name="press_geom" type="box" pos="0 0 0" size="0.012 0.012 0.005"
            rgba="0.8 0.3 0.3 1" contype="1" conaffinity="1"/>
    </body>
  </worldbody>

  <equality>
    <!-- ベベルギア(12T-36T)噛み合い: dome_joint = -motor_joint / 3 -->
    <joint joint1="dome_joint" joint2="motor_joint" polycoef="0 -0.33333333 0 0 0"/>
  </equality>

  <actuator>
    <motor name="turret_motor" joint="motor_joint"
           gear="10" ctrllimited="true" ctrlrange="-1 1"/>
    <position name="press_ctrl" joint="press_slide"
              kp="50" ctrllimited="true" ctrlrange="0.0 0.030"/>
    <position name="wall_x_ctrl" joint="wall_x"
              kp="50" ctrllimited="true" ctrlrange="-0.06 0.06"/>
    <position name="wall_y_ctrl" joint="wall_y"
              kp="50" ctrllimited="true" ctrlrange="-0.05 0.10"/>
  </actuator>

  <sensor>
    <!-- 旋回角度・角速度 -->
    <jointpos  name="turret_angle" joint="motor_joint"/>
    <jointvel  name="turret_vel"   joint="motor_joint"/>
    <jointpos  name="dome_angle"   joint="dome_joint"/>
    <jointvel  name="dome_vel"     joint="dome_joint"/>
    <!-- センサー位置・姿勢（ソナー取り付け面） -->
    <framepos  name="sonar_pos"  objtype="site" objname="sonar_site"/>
    <framequat name="sonar_quat" objtype="site" objname="sonar_site"/>
    <framepos  name="color_pos"  objtype="site" objname="color_site"/>
    <framequat name="color_quat" objtype="site" objname="color_site"/>
    <!-- 終了スイッチ -->
    <touch name="force_touch" site="force_site"/>
  </sensor>

</mujoco>
