<mujoco model="turtlebot3_burger_world">
  <compiler angle="radian"/>

  <option timestep="0.001" gravity="0 0 -9.81" integrator="implicit"/>

  <visual>
    <global offwidth="320" offheight="240"/>
    <map znear="0.05" zfar="10"/>
  </visual>

  <asset>
    <texture name="grid" type="2d" builtin="checker" width="512" height="512" rgb1="1 1 1" rgb2="0 0 0"/>
    <material name="grid" texture="grid" texrepeat="4 4" texuniform="true" reflectance="0.2"/>
    <texture name="ground_checker" type="2d" builtin="checker" width="128" height="128"
             rgb1="0.85 0.85 0.85" rgb2="0.65 0.65 0.65"/>
    <material name="ground_mat" texture="ground_checker" texrepeat="4 4" reflectance="0"/>
    <material name="red_mat" rgba="1 0 0 1"/>
    <material name="green_mat" rgba="0 1 0 1"/>
    <material name="blue_mat" rgba="0 0.2 1 1"/>
    <material name="sensor_mat" rgba="0.1 0.1 0.1 1"/>
    <material name="lens_mat" rgba="0.02 0.02 0.02 1"/>
    <material name="camera_forward_mat" rgba="1 1 0 1"/>


  </asset>

  <worldbody>
    <geom name="ground" type="plane" size="10 10 0.05" pos="0 0 0" material="grid" friction="1.0"/>

    <body name="obstacle_front" pos="1.0 0.0 0.2">
      <geom name="obstacle_front_geom" type="box" size="0.08 0.25 0.2" rgba="0.85 0.25 0.25 1"/>
    </body>

    <body name="obstacle_left" pos="0.7 0.45 0.15">
      <geom name="obstacle_left_geom" type="box" size="0.12 0.12 0.15" rgba="0.25 0.55 0.85 1"/>
    </body>

    <body name="obstacle_right" pos="0.7 -0.45 0.15">
      <geom name="obstacle_right_geom" type="cylinder" size="0.1 0.15" rgba="0.25 0.75 0.35 1"/>
    </body>

    <body name="ring_obstacle_000" pos="5.0 0.0 0.3">
      <geom type="cylinder" size="0.08 0.3" rgba="0.85 0.20 0.20 1"/>
    </body>
    <body name="ring_obstacle_030" pos="4.330 2.500 0.3">
      <geom type="cylinder" size="0.08 0.3" rgba="0.85 0.45 0.20 1"/>
    </body>
    <body name="ring_obstacle_060" pos="2.500 4.330 0.3">
      <geom type="cylinder" size="0.08 0.3" rgba="0.85 0.70 0.20 1"/>
    </body>
    <body name="ring_obstacle_090" pos="0.0 5.0 0.3">
      <geom type="cylinder" size="0.08 0.3" rgba="0.70 0.85 0.20 1"/>
    </body>
    <body name="ring_obstacle_120" pos="-2.500 4.330 0.3">
      <geom type="cylinder" size="0.08 0.3" rgba="0.40 0.85 0.20 1"/>
    </body>
    <body name="ring_obstacle_150" pos="-4.330 2.500 0.3">
      <geom type="cylinder" size="0.08 0.3" rgba="0.20 0.85 0.30 1"/>
    </body>
    <body name="ring_obstacle_180" pos="-5.0 0.0 0.3">
      <geom type="cylinder" size="0.08 0.3" rgba="0.20 0.85 0.55 1"/>
    </body>
    <body name="ring_obstacle_210" pos="-4.330 -2.500 0.3">
      <geom type="cylinder" size="0.08 0.3" rgba="0.20 0.75 0.85 1"/>
    </body>
    <body name="ring_obstacle_240" pos="-2.500 -4.330 0.3">
      <geom type="cylinder" size="0.08 0.3" rgba="0.20 0.50 0.85 1"/>
    </body>
    <body name="ring_obstacle_270" pos="0.0 -5.0 0.3">
      <geom type="cylinder" size="0.08 0.3" rgba="0.25 0.30 0.85 1"/>
    </body>
    <body name="ring_obstacle_300" pos="2.500 -4.330 0.3">
      <geom type="cylinder" size="0.08 0.3" rgba="0.50 0.25 0.85 1"/>
    </body>
    <body name="ring_obstacle_330" pos="4.330 -2.500 0.3">
      <geom type="cylinder" size="0.08 0.3" rgba="0.75 0.20 0.85 1"/>
    </body>

    <body name="base_footprint" pos="0 0 0.0">
      <freejoint/>
      <body name="base_link" pos="0 0 0.01">
        <inertial pos="0 0 0" quat="0.994532 -0.0072214 -0.0815456 -0.0648458" mass="0.825735" diaginertia="0.00221987 0.00211778 0.00200059"/>
        <geom size="0.07 0.07 0.0715" pos="-0.032 0 0.07" type="box" rgba="0.4 0.4 0.4 1"/>

        <body name="color_sensor_body" pos="0.056 0 0.1">
          <geom name="color_sensor_lens" type="cylinder" size="0.0125 0.006" pos="0 0 0"
                euler="0 1.57079632679 0" material="lens_mat"/>
          <camera name="color_camera" mode="fixed" pos="0 0 0" xyaxes="0 -1 0 0 0 1"/>
        </body>

        <body name="wheel_left_link" pos="0 0.08 0.023" quat="0.707388 -0.706825 0 0">
          <inertial pos="0 0 0" quat="-0.000890159 0.706886 0.000889646 0.707326" mass="0.0284989" diaginertia="2.07126e-05 1.11924e-05 1.11756e-05"/>
          <joint name="wheel_left_joint" type="hinge" pos="0 0 0" axis="0 0 1"/>
          <geom size="0.033 0.009" type="cylinder" rgba="0.3 0.3 0.3 1" friction="2.0 0.005 0.0001"/>
        </body>

        <body name="wheel_right_link" pos="0 -0.08 0.023" quat="0.707388 -0.706825 0 0">
          <inertial pos="0 0 0" quat="-0.000890159 0.706886 0.000889646 0.707326" mass="0.0284989" diaginertia="2.07126e-05 1.11924e-05 1.11756e-05"/>
          <joint name="wheel_right_joint" type="hinge" pos="0 0 0" axis="0 0 1"/>
          <geom size="0.033 0.009" type="cylinder" rgba="0.3 0.3 0.3 1" friction="2.0 0.005 0.0001"/>
        </body>

        <body name="caster_back_link" pos="-0.081 0 0" quat="0.707388 -0.706825 0 0">
          <inertial pos="0 0 0" mass="0.005" diaginertia="0.001 0.001 0.001"/>
          <joint name="caster_back_ball_joint" type="ball" damping="0.0005" armature="0.00001"/>
          <geom size="0.01" pos="0 0 0" type="sphere" friction="0.02 0.001 0.001" solref="0.02 1" contype="0" conaffinity="0"/>
        </body>

        <body name="imu_link" pos="-0.032 0 0.068"/>

        <body name="base_scan" pos="-0.032 0 0.172">
          <inertial pos="0 0 0" mass="0.114" diaginertia="0.001 0.001 0.001"/>
          <geom size="0.055 0.01575" pos="0.015 0 -0.0065" type="cylinder" rgba="0.3 0.3 0.3 1"/>
        </body>
      </body>
    </body>
  </worldbody>

  <actuator>
    <velocity name="left_motor" joint="wheel_left_joint" kv="0.75" ctrllimited="true" ctrlrange="-12 12"/>
    <velocity name="right_motor" joint="wheel_right_joint" kv="0.75" ctrllimited="true" ctrlrange="-12 12"/>
  </actuator>
</mujoco>
